nohup: ignoring input
2025-08-19 04:15:56,177 - __main__ - INFO - Telegram bot işə başlayır...
2025-08-19 04:15:56,433 - httpx - INFO - HTTP Request: POST https://api.telegram.org/bot7317862412:AAF_SaKYUI4kTqDamXElz8EQYA5v5EZD7AE/getMe "HTTP/1.1 200 OK"
2025-08-19 04:15:56,515 - httpx - INFO - HTTP Request: POST https://api.telegram.org/bot7317862412:AAF_SaKYUI4kTqDamXElz8EQYA5v5EZD7AE/deleteWebhook "HTTP/1.1 200 OK"
2025-08-19 04:15:56,516 - telegram.ext.Application - INFO - Application started
2025-08-19 04:16:00,870 - httpx - INFO - HTTP Request: POST https://api.telegram.org/bot7317862412:AAF_SaKYUI4kTqDamXElz8EQYA5v5EZD7AE/getUpdates "HTTP/1.1 409 Conflict"
2025-08-19 04:16:00,871 - telegram.ext.Application - ERROR - No error handlers are registered, logging exception.
Traceback (most recent call last):
  File "/home/ubuntu/phishing_bot/venv/lib/python3.11/site-packages/telegram/ext/_utils/networkloop.py", line 115, in network_retry_loop
    if not await do_action():
           ^^^^^^^^^^^^^^^^^
  File "/home/ubuntu/phishing_bot/venv/lib/python3.11/site-packages/telegram/ext/_utils/networkloop.py", line 108, in do_action
    return action_cb_task.result()
           ^^^^^^^^^^^^^^^^^^^^^^^
  File "/home/ubuntu/phishing_bot/venv/lib/python3.11/site-packages/telegram/ext/_updater.py", line 340, in polling_action_cb
    updates = await self.bot.get_updates(
              ^^^^^^^^^^^^^^^^^^^^^^^^^^^
  File "/home/ubuntu/phishing_bot/venv/lib/python3.11/site-packages/telegram/ext/_extbot.py", line 670, in get_updates
    updates = await super().get_updates(
              ^^^^^^^^^^^^^^^^^^^^^^^^^^
  File "/home/ubuntu/phishing_bot/venv/lib/python3.11/site-packages/telegram/_bot.py", line 4611, in get_updates
    await self._post(
  File "/home/ubuntu/phishing_bot/venv/lib/python3.11/site-packages/telegram/_bot.py", line 698, in _post
    return await self._do_post(
           ^^^^^^^^^^^^^^^^^^^^
  File "/home/ubuntu/phishing_bot/venv/lib/python3.11/site-packages/telegram/ext/_extbot.py", line 370, in _do_post
    return await super()._do_post(
           ^^^^^^^^^^^^^^^^^^^^^^^
  File "/home/ubuntu/phishing_bot/venv/lib/python3.11/site-packages/telegram/_bot.py", line 727, in _do_post
    result = await request.post(
             ^^^^^^^^^^^^^^^^^^^
  File "/home/ubuntu/phishing_bot/venv/lib/python3.11/site-packages/telegram/request/_baserequest.py", line 197, in post
    result = await self._request_wrapper(
             ^^^^^^^^^^^^^^^^^^^^^^^^^^^^
  File "/home/ubuntu/phishing_bot/venv/lib/python3.11/site-packages/telegram/request/_baserequest.py", line 374, in _request_wrapper
    raise exception
telegram.error.Conflict: Conflict: terminated by other getUpdates request; make sure that only one bot instance is running
2025-08-19 04:16:06,552 - httpx - INFO - HTTP Request: POST https://api.telegram.org/bot7317862412:AAF_SaKYUI4kTqDamXElz8EQYA5v5EZD7AE/getUpdates "HTTP/1.1 409 Conflict"
2025-08-19 04:16:06,553 - telegram.ext.Application - ERROR - No error handlers are registered, logging exception.
Traceback (most recent call last):
  File "/home/ubuntu/phishing_bot/venv/lib/python3.11/site-packages/telegram/ext/_utils/networkloop.py", line 115, in network_retry_loop
    if not await do_action():
           ^^^^^^^^^^^^^^^^^
  File "/home/ubuntu/phishing_bot/venv/lib/python3.11/site-packages/telegram/ext/_utils/networkloop.py", line 108, in do_action
    return action_cb_task.result()
           ^^^^^^^^^^^^^^^^^^^^^^^
  File "/home/ubuntu/phishing_bot/venv/lib/python3.11/site-packages/telegram/ext/_updater.py", line 340, in polling_action_cb
    updates = await self.bot.get_updates(
              ^^^^^^^^^^^^^^^^^^^^^^^^^^^
  File "/home/ubuntu/phishing_bot/venv/lib/python3.11/site-packages/telegram/ext/_extbot.py", line 670, in get_updates
    updates = await super().get_updates(
              ^^^^^^^^^^^^^^^^^^^^^^^^^^
  File "/home/ubuntu/phishing_bot/venv/lib/python3.11/site-packages/telegram/_bot.py", line 4611, in get_updates
    await self._post(
  File "/home/ubuntu/phishing_bot/venv/lib/python3.11/site-packages/telegram/_bot.py", line 698, in _post
    return await self._do_post(
           ^^^^^^^^^^^^^^^^^^^^
  File "/home/ubuntu/phishing_bot/venv/lib/python3.11/site-packages/telegram/ext/_extbot.py", line 370, in _do_post
    return await super()._do_post(
           ^^^^^^^^^^^^^^^^^^^^^^^
  File "/home/ubuntu/phishing_bot/venv/lib/python3.11/site-packages/telegram/_bot.py", line 727, in _do_post
    result = await request.post(
             ^^^^^^^^^^^^^^^^^^^
  File "/home/ubuntu/phishing_bot/venv/lib/python3.11/site-packages/telegram/request/_baserequest.py", line 197, in post
    result = await self._request_wrapper(
             ^^^^^^^^^^^^^^^^^^^^^^^^^^^^
  File "/home/ubuntu/phishing_bot/venv/lib/python3.11/site-packages/telegram/request/_baserequest.py", line 374, in _request_wrapper
    raise exception
telegram.error.Conflict: Conflict: terminated by other getUpdates request; make sure that only one bot instance is running
2025-08-19 04:16:08,331 - httpx - INFO - HTTP Request: POST https://api.telegram.org/bot7317862412:AAF_SaKYUI4kTqDamXElz8EQYA5v5EZD7AE/getUpdates "HTTP/1.1 200 OK"
2025-08-19 04:16:08,610 - httpx - INFO - HTTP Request: POST https://api.telegram.org/bot7317862412:AAF_SaKYUI4kTqDamXElz8EQYA5v5EZD7AE/sendMessage "HTTP/1.1 200 OK"
2025-08-19 04:16:13,487 - httpx - INFO - HTTP Request: POST https://api.telegram.org/bot7317862412:AAF_SaKYUI4kTqDamXElz8EQYA5v5EZD7AE/getUpdates "HTTP/1.1 409 Conflict"
2025-08-19 04:16:13,487 - telegram.ext.Application - ERROR - No error handlers are registered, logging exception.
Traceback (most recent call last):
  File "/home/ubuntu/phishing_bot/venv/lib/python3.11/site-packages/telegram/ext/_utils/networkloop.py", line 115, in network_retry_loop
    if not await do_action():
           ^^^^^^^^^^^^^^^^^
  File "/home/ubuntu/phishing_bot/venv/lib/python3.11/site-packages/telegram/ext/_utils/networkloop.py", line 108, in do_action
    return action_cb_task.result()
           ^^^^^^^^^^^^^^^^^^^^^^^
  File "/home/ubuntu/phishing_bot/venv/lib/python3.11/site-packages/telegram/ext/_updater.py", line 340, in polling_action_cb
    updates = await self.bot.get_updates(
              ^^^^^^^^^^^^^^^^^^^^^^^^^^^
  File "/home/ubuntu/phishing_bot/venv/lib/python3.11/site-packages/telegram/ext/_extbot.py", line 670, in get_updates
    updates = await super().get_updates(
              ^^^^^^^^^^^^^^^^^^^^^^^^^^
  File "/home/ubuntu/phishing_bot/venv/lib/python3.11/site-packages/telegram/_bot.py", line 4611, in get_updates
    await self._post(
  File "/home/ubuntu/phishing_bot/venv/lib/python3.11/site-packages/telegram/_bot.py", line 698, in _post
    return await self._do_post(
           ^^^^^^^^^^^^^^^^^^^^
  File "/home/ubuntu/phishing_bot/venv/lib/python3.11/site-packages/telegram/ext/_extbot.py", line 370, in _do_post
    return await super()._do_post(
           ^^^^^^^^^^^^^^^^^^^^^^^
  File "/home/ubuntu/phishing_bot/venv/lib/python3.11/site-packages/telegram/_bot.py", line 727, in _do_post
    result = await request.post(
             ^^^^^^^^^^^^^^^^^^^
  File "/home/ubuntu/phishing_bot/venv/lib/python3.11/site-packages/telegram/request/_baserequest.py", line 197, in post
    result = await self._request_wrapper(
             ^^^^^^^^^^^^^^^^^^^^^^^^^^^^
  File "/home/ubuntu/phishing_bot/venv/lib/python3.11/site-packages/telegram/request/_baserequest.py", line 374, in _request_wrapper
    raise exception
telegram.error.Conflict: Conflict: terminated by other getUpdates request; make sure that only one bot instance is running
2025-08-19 04:16:18,046 - httpx - INFO - HTTP Request: POST https://api.telegram.org/bot7317862412:AAF_SaKYUI4kTqDamXElz8EQYA5v5EZD7AE/getUpdates "HTTP/1.1 409 Conflict"
2025-08-19 04:16:18,046 - telegram.ext.Application - ERROR - No error handlers are registered, logging exception.
Traceback (most recent call last):
  File "/home/ubuntu/phishing_bot/venv/lib/python3.11/site-packages/telegram/ext/_utils/networkloop.py", line 115, in network_retry_loop
    if not await do_action():
           ^^^^^^^^^^^^^^^^^
  File "/home/ubuntu/phishing_bot/venv/lib/python3.11/site-packages/telegram/ext/_utils/networkloop.py", line 108, in do_action
    return action_cb_task.result()
           ^^^^^^^^^^^^^^^^^^^^^^^
  File "/home/ubuntu/phishing_bot/venv/lib/python3.11/site-packages/telegram/ext/_updater.py", line 340, in polling_action_cb
    updates = await self.bot.get_updates(
              ^^^^^^^^^^^^^^^^^^^^^^^^^^^
  File "/home/ubuntu/phishing_bot/venv/lib/python3.11/site-packages/telegram/ext/_extbot.py", line 670, in get_updates
    updates = await super().get_updates(
              ^^^^^^^^^^^^^^^^^^^^^^^^^^
  File "/home/ubuntu/phishing_bot/venv/lib/python3.11/site-packages/telegram/_bot.py", line 4611, in get_updates
    await self._post(
  File "/home/ubuntu/phishing_bot/venv/lib/python3.11/site-packages/telegram/_bot.py", line 698, in _post
    return await self._do_post(
           ^^^^^^^^^^^^^^^^^^^^
  File "/home/ubuntu/phishing_bot/venv/lib/python3.11/site-packages/telegram/ext/_extbot.py", line 370, in _do_post
    return await super()._do_post(
           ^^^^^^^^^^^^^^^^^^^^^^^
  File "/home/ubuntu/phishing_bot/venv/lib/python3.11/site-packages/telegram/_bot.py", line 727, in _do_post
    result = await request.post(
             ^^^^^^^^^^^^^^^^^^^
  File "/home/ubuntu/phishing_bot/venv/lib/python3.11/site-packages/telegram/request/_baserequest.py", line 197, in post
    result = await self._request_wrapper(
             ^^^^^^^^^^^^^^^^^^^^^^^^^^^^
  File "/home/ubuntu/phishing_bot/venv/lib/python3.11/site-packages/telegram/request/_baserequest.py", line 374, in _request_wrapper
    raise exception
telegram.error.Conflict: Conflict: terminated by other getUpdates request; make sure that only one bot instance is running
2025-08-19 04:16:27,970 - httpx - INFO - HTTP Request: POST https://api.telegram.org/bot7317862412:AAF_SaKYUI4kTqDamXElz8EQYA5v5EZD7AE/getUpdates "HTTP/1.1 409 Conflict"
2025-08-19 04:16:27,971 - telegram.ext.Application - ERROR - No error handlers are registered, logging exception.
Traceback (most recent call last):
  File "/home/ubuntu/phishing_bot/venv/lib/python3.11/site-packages/telegram/ext/_utils/networkloop.py", line 115, in network_retry_loop
    if not await do_action():
           ^^^^^^^^^^^^^^^^^
  File "/home/ubuntu/phishing_bot/venv/lib/python3.11/site-packages/telegram/ext/_utils/networkloop.py", line 108, in do_action
    return action_cb_task.result()
           ^^^^^^^^^^^^^^^^^^^^^^^
  File "/home/ubuntu/phishing_bot/venv/lib/python3.11/site-packages/telegram/ext/_updater.py", line 340, in polling_action_cb
    updates = await self.bot.get_updates(
              ^^^^^^^^^^^^^^^^^^^^^^^^^^^
  File "/home/ubuntu/phishing_bot/venv/lib/python3.11/site-packages/telegram/ext/_extbot.py", line 670, in get_updates
    updates = await super().get_updates(
              ^^^^^^^^^^^^^^^^^^^^^^^^^^
  File "/home/ubuntu/phishing_bot/venv/lib/python3.11/site-packages/telegram/_bot.py", line 4611, in get_updates
    await self._post(
  File "/home/ubuntu/phishing_bot/venv/lib/python3.11/site-packages/telegram/_bot.py", line 698, in _post
    return await self._do_post(
           ^^^^^^^^^^^^^^^^^^^^
  File "/home/ubuntu/phishing_bot/venv/lib/python3.11/site-packages/telegram/ext/_extbot.py", line 370, in _do_post
    return await super()._do_post(
           ^^^^^^^^^^^^^^^^^^^^^^^
  File "/home/ubuntu/phishing_bot/venv/lib/python3.11/site-packages/telegram/_bot.py", line 727, in _do_post
    result = await request.post(
             ^^^^^^^^^^^^^^^^^^^
  File "/home/ubuntu/phishing_bot/venv/lib/python3.11/site-packages/telegram/request/_baserequest.py", line 197, in post
    result = await self._request_wrapper(
             ^^^^^^^^^^^^^^^^^^^^^^^^^^^^
  File "/home/ubuntu/phishing_bot/venv/lib/python3.11/site-packages/telegram/request/_baserequest.py", line 374, in _request_wrapper
    raise exception
telegram.error.Conflict: Conflict: terminated by other getUpdates request; make sure that only one bot instance is running
2025-08-19 04:16:40,321 - httpx - INFO - HTTP Request: POST https://api.telegram.org/bot7317862412:AAF_SaKYUI4kTqDamXElz8EQYA5v5EZD7AE/getUpdates "HTTP/1.1 200 OK"
2025-08-19 04:16:41,195 - httpx - INFO - HTTP Request: POST https://api.telegram.org/bot7317862412:AAF_SaKYUI4kTqDamXElz8EQYA5v5EZD7AE/getUpdates "HTTP/1.1 409 Conflict"
2025-08-19 04:16:41,195 - telegram.ext.Application - ERROR - No error handlers are registered, logging exception.
Traceback (most recent call last):
  File "/home/ubuntu/phishing_bot/venv/lib/python3.11/site-packages/telegram/ext/_utils/networkloop.py", line 115, in network_retry_loop
    if not await do_action():
           ^^^^^^^^^^^^^^^^^
  File "/home/ubuntu/phishing_bot/venv/lib/python3.11/site-packages/telegram/ext/_utils/networkloop.py", line 108, in do_action
    return action_cb_task.result()
           ^^^^^^^^^^^^^^^^^^^^^^^
  File "/home/ubuntu/phishing_bot/venv/lib/python3.11/site-packages/telegram/ext/_updater.py", line 340, in polling_action_cb
    updates = await self.bot.get_updates(
              ^^^^^^^^^^^^^^^^^^^^^^^^^^^
  File "/home/ubuntu/phishing_bot/venv/lib/python3.11/site-packages/telegram/ext/_extbot.py", line 670, in get_updates
    updates = await super().get_updates(
              ^^^^^^^^^^^^^^^^^^^^^^^^^^
  File "/home/ubuntu/phishing_bot/venv/lib/python3.11/site-packages/telegram/_bot.py", line 4611, in get_updates
    await self._post(
  File "/home/ubuntu/phishing_bot/venv/lib/python3.11/site-packages/telegram/_bot.py", line 698, in _post
    return await self._do_post(
           ^^^^^^^^^^^^^^^^^^^^
  File "/home/ubuntu/phishing_bot/venv/lib/python3.11/site-packages/telegram/ext/_extbot.py", line 370, in _do_post
    return await super()._do_post(
           ^^^^^^^^^^^^^^^^^^^^^^^
  File "/home/ubuntu/phishing_bot/venv/lib/python3.11/site-packages/telegram/_bot.py", line 727, in _do_post
    result = await request.post(
             ^^^^^^^^^^^^^^^^^^^
  File "/home/ubuntu/phishing_bot/venv/lib/python3.11/site-packages/telegram/request/_baserequest.py", line 197, in post
    result = await self._request_wrapper(
             ^^^^^^^^^^^^^^^^^^^^^^^^^^^^
  File "/home/ubuntu/phishing_bot/venv/lib/python3.11/site-packages/telegram/request/_baserequest.py", line 374, in _request_wrapper
    raise exception
telegram.error.Conflict: Conflict: terminated by other getUpdates request; make sure that only one bot instance is running
2025-08-19 04:16:52,286 - httpx - INFO - HTTP Request: POST https://api.telegram.org/bot7317862412:AAF_SaKYUI4kTqDamXElz8EQYA5v5EZD7AE/getUpdates "HTTP/1.1 200 OK"
2025-08-19 04:16:56,932 - httpx - INFO - HTTP Request: POST https://api.telegram.org/bot7317862412:AAF_SaKYUI4kTqDamXElz8EQYA5v5EZD7AE/getUpdates "HTTP/1.1 409 Conflict"
2025-08-19 04:16:56,933 - telegram.ext.Application - ERROR - No error handlers are registered, logging exception.
Traceback (most recent call last):
  File "/home/ubuntu/phishing_bot/venv/lib/python3.11/site-packages/telegram/ext/_utils/networkloop.py", line 115, in network_retry_loop
    if not await do_action():
           ^^^^^^^^^^^^^^^^^
  File "/home/ubuntu/phishing_bot/venv/lib/python3.11/site-packages/telegram/ext/_utils/networkloop.py", line 108, in do_action
    return action_cb_task.result()
           ^^^^^^^^^^^^^^^^^^^^^^^
  File "/home/ubuntu/phishing_bot/venv/lib/python3.11/site-packages/telegram/ext/_updater.py", line 340, in polling_action_cb
    updates = await self.bot.get_updates(
              ^^^^^^^^^^^^^^^^^^^^^^^^^^^
  File "/home/ubuntu/phishing_bot/venv/lib/python3.11/site-packages/telegram/ext/_extbot.py", line 670, in get_updates
    updates = await super().get_updates(
              ^^^^^^^^^^^^^^^^^^^^^^^^^^
  File "/home/ubuntu/phishing_bot/venv/lib/python3.11/site-packages/telegram/_bot.py", line 4611, in get_updates
    await self._post(
  File "/home/ubuntu/phishing_bot/venv/lib/python3.11/site-packages/telegram/_bot.py", line 698, in _post
    return await self._do_post(
           ^^^^^^^^^^^^^^^^^^^^
  File "/home/ubuntu/phishing_bot/venv/lib/python3.11/site-packages/telegram/ext/_extbot.py", line 370, in _do_post
    return await super()._do_post(
           ^^^^^^^^^^^^^^^^^^^^^^^
  File "/home/ubuntu/phishing_bot/venv/lib/python3.11/site-packages/telegram/_bot.py", line 727, in _do_post
    result = await request.post(
             ^^^^^^^^^^^^^^^^^^^
  File "/home/ubuntu/phishing_bot/venv/lib/python3.11/site-packages/telegram/request/_baserequest.py", line 197, in post
    result = await self._request_wrapper(
             ^^^^^^^^^^^^^^^^^^^^^^^^^^^^
  File "/home/ubuntu/phishing_bot/venv/lib/python3.11/site-packages/telegram/request/_baserequest.py", line 374, in _request_wrapper
    raise exception
telegram.error.Conflict: Conflict: terminated by other getUpdates request; make sure that only one bot instance is running
2025-08-19 04:17:08,025 - httpx - INFO - HTTP Request: POST https://api.telegram.org/bot7317862412:AAF_SaKYUI4kTqDamXElz8EQYA5v5EZD7AE/getUpdates "HTTP/1.1 200 OK"
2025-08-19 04:17:10,857 - httpx - INFO - HTTP Request: POST https://api.telegram.org/bot7317862412:AAF_SaKYUI4kTqDamXElz8EQYA5v5EZD7AE/getUpdates "HTTP/1.1 200 OK"
2025-08-19 04:17:11,261 - httpx - INFO - HTTP Request: POST https://api.telegram.org/bot7317862412:AAF_SaKYUI4kTqDamXElz8EQYA5v5EZD7AE/sendMessage "HTTP/1.1 200 OK"
2025-08-19 04:17:18,384 - httpx - INFO - HTTP Request: POST https://api.telegram.org/bot7317862412:AAF_SaKYUI4kTqDamXElz8EQYA5v5EZD7AE/getUpdates "HTTP/1.1 409 Conflict"
2025-08-19 04:17:18,385 - telegram.ext.Application - ERROR - No error handlers are registered, logging exception.
Traceback (most recent call last):
  File "/home/ubuntu/phishing_bot/venv/lib/python3.11/site-packages/telegram/ext/_utils/networkloop.py", line 115, in network_retry_loop
    if not await do_action():
           ^^^^^^^^^^^^^^^^^
  File "/home/ubuntu/phishing_bot/venv/lib/python3.11/site-packages/telegram/ext/_utils/networkloop.py", line 108, in do_action
    return action_cb_task.result()
           ^^^^^^^^^^^^^^^^^^^^^^^
  File "/home/ubuntu/phishing_bot/venv/lib/python3.11/site-packages/telegram/ext/_updater.py", line 340, in polling_action_cb
    updates = await self.bot.get_updates(
              ^^^^^^^^^^^^^^^^^^^^^^^^^^^
  File "/home/ubuntu/phishing_bot/venv/lib/python3.11/site-packages/telegram/ext/_extbot.py", line 670, in get_updates
    updates = await super().get_updates(
              ^^^^^^^^^^^^^^^^^^^^^^^^^^
  File "/home/ubuntu/phishing_bot/venv/lib/python3.11/site-packages/telegram/_bot.py", line 4611, in get_updates
    await self._post(
  File "/home/ubuntu/phishing_bot/venv/lib/python3.11/site-packages/telegram/_bot.py", line 698, in _post
    return await self._do_post(
           ^^^^^^^^^^^^^^^^^^^^
  File "/home/ubuntu/phishing_bot/venv/lib/python3.11/site-packages/telegram/ext/_extbot.py", line 370, in _do_post
    return await super()._do_post(
           ^^^^^^^^^^^^^^^^^^^^^^^
  File "/home/ubuntu/phishing_bot/venv/lib/python3.11/site-packages/telegram/_bot.py", line 727, in _do_post
    result = await request.post(
             ^^^^^^^^^^^^^^^^^^^
  File "/home/ubuntu/phishing_bot/venv/lib/python3.11/site-packages/telegram/request/_baserequest.py", line 197, in post
    result = await self._request_wrapper(
             ^^^^^^^^^^^^^^^^^^^^^^^^^^^^
  File "/home/ubuntu/phishing_bot/venv/lib/python3.11/site-packages/telegram/request/_baserequest.py", line 374, in _request_wrapper
    raise exception
telegram.error.Conflict: Conflict: terminated by other getUpdates request; make sure that only one bot instance is running
2025-08-19 04:17:29,481 - httpx - INFO - HTTP Request: POST https://api.telegram.org/bot7317862412:AAF_SaKYUI4kTqDamXElz8EQYA5v5EZD7AE/getUpdates "HTTP/1.1 200 OK"
2025-08-19 04:17:39,571 - httpx - INFO - HTTP Request: POST https://api.telegram.org/bot7317862412:AAF_SaKYUI4kTqDamXElz8EQYA5v5EZD7AE/getUpdates "HTTP/1.1 200 OK"
2025-08-19 04:17:48,401 - httpx - INFO - HTTP Request: POST https://api.telegram.org/bot7317862412:AAF_SaKYUI4kTqDamXElz8EQYA5v5EZD7AE/getUpdates "HTTP/1.1 409 Conflict"
2025-08-19 04:17:48,401 - telegram.ext.Application - ERROR - No error handlers are registered, logging exception.
Traceback (most recent call last):
  File "/home/ubuntu/phishing_bot/venv/lib/python3.11/site-packages/telegram/ext/_utils/networkloop.py", line 115, in network_retry_loop
    if not await do_action():
           ^^^^^^^^^^^^^^^^^
  File "/home/ubuntu/phishing_bot/venv/lib/python3.11/site-packages/telegram/ext/_utils/networkloop.py", line 108, in do_action
    return action_cb_task.result()
           ^^^^^^^^^^^^^^^^^^^^^^^
  File "/home/ubuntu/phishing_bot/venv/lib/python3.11/site-packages/telegram/ext/_updater.py", line 340, in polling_action_cb
    updates = await self.bot.get_updates(
              ^^^^^^^^^^^^^^^^^^^^^^^^^^^
  File "/home/ubuntu/phishing_bot/venv/lib/python3.11/site-packages/telegram/ext/_extbot.py", line 670, in get_updates
    updates = await super().get_updates(
              ^^^^^^^^^^^^^^^^^^^^^^^^^^
  File "/home/ubuntu/phishing_bot/venv/lib/python3.11/site-packages/telegram/_bot.py", line 4611, in get_updates
    await self._post(
  File "/home/ubuntu/phishing_bot/venv/lib/python3.11/site-packages/telegram/_bot.py", line 698, in _post
    return await self._do_post(
           ^^^^^^^^^^^^^^^^^^^^
  File "/home/ubuntu/phishing_bot/venv/lib/python3.11/site-packages/telegram/ext/_extbot.py", line 370, in _do_post
    return await super()._do_post(
           ^^^^^^^^^^^^^^^^^^^^^^^
  File "/home/ubuntu/phishing_bot/venv/lib/python3.11/site-packages/telegram/_bot.py", line 727, in _do_post
    result = await request.post(
             ^^^^^^^^^^^^^^^^^^^
  File "/home/ubuntu/phishing_bot/venv/lib/python3.11/site-packages/telegram/request/_baserequest.py", line 197, in post
    result = await self._request_wrapper(
             ^^^^^^^^^^^^^^^^^^^^^^^^^^^^
  File "/home/ubuntu/phishing_bot/venv/lib/python3.11/site-packages/telegram/request/_baserequest.py", line 374, in _request_wrapper
    raise exception
telegram.error.Conflict: Conflict: terminated by other getUpdates request; make sure that only one bot instance is running
2025-08-19 04:17:59,496 - httpx - INFO - HTTP Request: POST https://api.telegram.org/bot7317862412:AAF_SaKYUI4kTqDamXElz8EQYA5v5EZD7AE/getUpdates "HTTP/1.1 200 OK"
2025-08-19 04:18:09,595 - httpx - INFO - HTTP Request: POST https://api.telegram.org/bot7317862412:AAF_SaKYUI4kTqDamXElz8EQYA5v5EZD7AE/getUpdates "HTTP/1.1 200 OK"
2025-08-19 04:18:19,685 - httpx - INFO - HTTP Request: POST https://api.telegram.org/bot7317862412:AAF_SaKYUI4kTqDamXElz8EQYA5v5EZD7AE/getUpdates "HTTP/1.1 200 OK"
2025-08-19 04:18:22,775 - httpx - INFO - HTTP Request: POST https://api.telegram.org/bot7317862412:AAF_SaKYUI4kTqDamXElz8EQYA5v5EZD7AE/getUpdates "HTTP/1.1 409 Conflict"
2025-08-19 04:18:22,775 - telegram.ext.Application - ERROR - No error handlers are registered, logging exception.
Traceback (most recent call last):
  File "/home/ubuntu/phishing_bot/venv/lib/python3.11/site-packages/telegram/ext/_utils/networkloop.py", line 115, in network_retry_loop
    if not await do_action():
           ^^^^^^^^^^^^^^^^^
  File "/home/ubuntu/phishing_bot/venv/lib/python3.11/site-packages/telegram/ext/_utils/networkloop.py", line 108, in do_action
    return action_cb_task.result()
           ^^^^^^^^^^^^^^^^^^^^^^^
  File "/home/ubuntu/phishing_bot/venv/lib/python3.11/site-packages/telegram/ext/_updater.py", line 340, in polling_action_cb
    updates = await self.bot.get_updates(
              ^^^^^^^^^^^^^^^^^^^^^^^^^^^
  File "/home/ubuntu/phishing_bot/venv/lib/python3.11/site-packages/telegram/ext/_extbot.py", line 670, in get_updates
    updates = await super().get_updates(
              ^^^^^^^^^^^^^^^^^^^^^^^^^^
  File "/home/ubuntu/phishing_bot/venv/lib/python3.11/site-packages/telegram/_bot.py", line 4611, in get_updates
    await self._post(
  File "/home/ubuntu/phishing_bot/venv/lib/python3.11/site-packages/telegram/_bot.py", line 698, in _post
    return await self._do_post(
           ^^^^^^^^^^^^^^^^^^^^
  File "/home/ubuntu/phishing_bot/venv/lib/python3.11/site-packages/telegram/ext/_extbot.py", line 370, in _do_post
    return await super()._do_post(
           ^^^^^^^^^^^^^^^^^^^^^^^
  File "/home/ubuntu/phishing_bot/venv/lib/python3.11/site-packages/telegram/_bot.py", line 727, in _do_post
    result = await request.post(
             ^^^^^^^^^^^^^^^^^^^
  File "/home/ubuntu/phishing_bot/venv/lib/python3.11/site-packages/telegram/request/_baserequest.py", line 197, in post
    result = await self._request_wrapper(
             ^^^^^^^^^^^^^^^^^^^^^^^^^^^^
  File "/home/ubuntu/phishing_bot/venv/lib/python3.11/site-packages/telegram/request/_baserequest.py", line 374, in _request_wrapper
    raise exception
telegram.error.Conflict: Conflict: terminated by other getUpdates request; make sure that only one bot instance is running
2025-08-19 04:18:33,871 - httpx - INFO - HTTP Request: POST https://api.telegram.org/bot7317862412:AAF_SaKYUI4kTqDamXElz8EQYA5v5EZD7AE/getUpdates "HTTP/1.1 200 OK"
2025-08-19 04:18:43,961 - httpx - INFO - HTTP Request: POST https://api.telegram.org/bot7317862412:AAF_SaKYUI4kTqDamXElz8EQYA5v5EZD7AE/getUpdates "HTTP/1.1 200 OK"
2025-08-19 04:18:54,050 - httpx - INFO - HTTP Request: POST https://api.telegram.org/bot7317862412:AAF_SaKYUI4kTqDamXElz8EQYA5v5EZD7AE/getUpdates "HTTP/1.1 200 OK"
2025-08-19 04:18:57,170 - httpx - INFO - HTTP Request: POST https://api.telegram.org/bot7317862412:AAF_SaKYUI4kTqDamXElz8EQYA5v5EZD7AE/getUpdates "HTTP/1.1 409 Conflict"
2025-08-19 04:18:57,171 - telegram.ext.Application - ERROR - No error handlers are registered, logging exception.
Traceback (most recent call last):
  File "/home/ubuntu/phishing_bot/venv/lib/python3.11/site-packages/telegram/ext/_utils/networkloop.py", line 115, in network_retry_loop
    if not await do_action():
           ^^^^^^^^^^^^^^^^^
  File "/home/ubuntu/phishing_bot/venv/lib/python3.11/site-packages/telegram/ext/_utils/networkloop.py", line 108, in do_action
    return action_cb_task.result()
           ^^^^^^^^^^^^^^^^^^^^^^^
  File "/home/ubuntu/phishing_bot/venv/lib/python3.11/site-packages/telegram/ext/_updater.py", line 340, in polling_action_cb
    updates = await self.bot.get_updates(
              ^^^^^^^^^^^^^^^^^^^^^^^^^^^
  File "/home/ubuntu/phishing_bot/venv/lib/python3.11/site-packages/telegram/ext/_extbot.py", line 670, in get_updates
    updates = await super().get_updates(
              ^^^^^^^^^^^^^^^^^^^^^^^^^^
  File "/home/ubuntu/phishing_bot/venv/lib/python3.11/site-packages/telegram/_bot.py", line 4611, in get_updates
    await self._post(
  File "/home/ubuntu/phishing_bot/venv/lib/python3.11/site-packages/telegram/_bot.py", line 698, in _post
    return await self._do_post(
           ^^^^^^^^^^^^^^^^^^^^
  File "/home/ubuntu/phishing_bot/venv/lib/python3.11/site-packages/telegram/ext/_extbot.py", line 370, in _do_post
    return await super()._do_post(
           ^^^^^^^^^^^^^^^^^^^^^^^
  File "/home/ubuntu/phishing_bot/venv/lib/python3.11/site-packages/telegram/_bot.py", line 727, in _do_post
    result = await request.post(
             ^^^^^^^^^^^^^^^^^^^
  File "/home/ubuntu/phishing_bot/venv/lib/python3.11/site-packages/telegram/request/_baserequest.py", line 197, in post
    result = await self._request_wrapper(
             ^^^^^^^^^^^^^^^^^^^^^^^^^^^^
  File "/home/ubuntu/phishing_bot/venv/lib/python3.11/site-packages/telegram/request/_baserequest.py", line 374, in _request_wrapper
    raise exception
telegram.error.Conflict: Conflict: terminated by other getUpdates request; make sure that only one bot instance is running
